Workbook

Sheet Sheet1 (2)
A1: Dates I Called BPD | B1: BPD LTC Queue Date | C1: LTC In-Hand Date | D1: App-Days Advanced | E1: Workdays Elapsed | F1: Pace (app-days/ workdays) | G1: Cumulative App-Days Completed | H1: Cumulative Work-Days Completed | I1: Cumulative Pace | J1: Backlog Amount (Days) | K1: Projected Date using Average of Cumulative Pace if you applied today | L1: Projected Date using slope equation if you were to apply today
A2: 45889 | B2: 45676 | J2: =_xlfn.DAYS(A2,B2) -> 213 | K2: =IFERROR(WORKDAY($A2, ROUNDUP(MAX(0, _xlfn.DAYS($A2, $B2)) / $I$40, 0),Sheet2!$A$2:$A$21),"") -> 46120 | L2: =A2*1.00474635070856 -> 46106.805
A3: 45908 | B3: 45690 | D3: =IF(B3="","",B3-B2) -> 14 | E3: =IF(A3="","",NETWORKDAYS(A2,A3,Sheet2!$A$2:$A$21)-1) -> 12 | F3: =D3/E3 -> 1.1666667 | G3: =SUM($D$3:D3) -> 14 | H3: =SUM($E$3:E3) -> 12 | I3: =G3/H3 -> 1.1666667 | J3: =_xlfn.DAYS(A3,B3) -> 218 | K3: =IFERROR(WORKDAY($A3, ROUNDUP(MAX(0, _xlfn.DAYS($A3, $B3)) / $I$40, 0),Sheet2!$A$2:$A$21),"") -> 46142 | L3: =A3*1.00474635070856 -> 46125.895
A4: 45915 | B4: 45698 | D4: =IF(B4="","",B4-B3) -> 8 | E4: =IF(A4="","",NETWORKDAYS(A3,A4,Sheet2!$A$2:$A$21)-1) -> 5 | F4: =D4/E4 -> 1.6 | G4: =SUM($D$3:D4) -> 22 | H4: =SUM($E$3:E4) -> 17 | I4: =G4/H4 -> 1.2941176 | J4: =_xlfn.DAYS(A4,B4) -> 217 | K4: =IFERROR(WORKDAY($A4, ROUNDUP(MAX(0, _xlfn.DAYS($A4, $B4)) / $I$40, 0),Sheet2!$A$2:$A$21),"") -> 46148 | L4: =A4*1.00474635070856 -> 46132.929
A5: 45919 | B5: 45707 | D5: =IF(B5="","",B5-B4) -> 9 | E5: =IF(A5="","",NETWORKDAYS(A4,A5,Sheet2!$A$2:$A$21)-1) -> 4 | F5: =D5/E5 -> 2.25 | G5: =SUM($D$3:D5) -> 31 | H5: =SUM($E$3:E5) -> 21 | I5: =G5/H5 -> 1.4761905 | J5: =_xlfn.DAYS(A5,B5) -> 212 | K5: =IFERROR(WORKDAY($A5, ROUNDUP(MAX(0, _xlfn.DAYS($A5, $B5)) / $I$40, 0),Sheet2!$A$2:$A$21),"") -> 46149 | L5: =A5*1.00474635070856 -> 46136.948
A6: 45923 | B6: 45709 | D6: =IF(B6="","",B6-B5) -> 2 | E6: =IF(A6="","",NETWORKDAYS(A5,A6,Sheet2!$A$2:$A$21)-1) -> 2 | F6: =D6/E6 -> 1 | G6: =SUM($D$3:D6) -> 33 | H6: =SUM($E$3:E6) -> 23 | I6: =G6/H6 -> 1.4347826 | J6: =_xlfn.DAYS(A6,B6) -> 214 | K6: =IFERROR(WORKDAY($A6, ROUNDUP(MAX(0, _xlfn.DAYS($A6, $B6)) / $I$40, 0),Sheet2!$A$2:$A$21),"") -> 46154 | L6: =A6*1.00474635070856 -> 46140.967
A7: 45924 | B7: 45712 | D7: =IF(B7="","",B7-B6) -> 3 | E7: =IF(A7="","",NETWORKDAYS(A6,A7,Sheet2!$A$2:$A$21)-1) -> 1 | F7: =D7/E7 -> 3 | G7: =SUM($D$3:D7) -> 36 | H7: =SUM($E$3:E7) -> 24 | I7: =G7/H7 -> 1.5 | J7: =_xlfn.DAYS(A7,B7) -> 212 | K7: =IFERROR(WORKDAY($A7, ROUNDUP(MAX(0, _xlfn.DAYS($A7, $B7)) / $I$40, 0),Sheet2!$A$2:$A$21),"") -> 46154 | L7: =A7*1.00474635070856 -> 46141.971
A8: 45926 | B8: 45712 | D8: 0.5 | E8: =IF(A8="","",NETWORKDAYS(A7,A8,Sheet2!$A$2:$A$21)-1) -> 2 | F8: =D8/E8 -> 0.25 | G8: =SUM($D$3:D8) -> 36.5 | H8: =SUM($E$3:E8) -> 26 | I8: =G8/H8 -> 1.4038462 | J8: =_xlfn.DAYS(A8,B8) -> 214 | K8: =IFERROR(WORKDAY($A8, ROUNDUP(MAX(0, _xlfn.DAYS($A8, $B8)) / $I$40, 0),Sheet2!$A$2:$A$21),"") -> 46157 | L8: =A8*1.00474635070856 -> 46143.981
A9: 45929 | B9: 45712 | D9: 0.25 | E9: =IF(A9="","",NETWORKDAYS(A8,A9,Sheet2!$A$2:$A$21)-1) -> 1 | F9: =D9/E9 -> 0.25 | G9: =SUM($D$3:D9) -> 36.75 | H9: =SUM($E$3:E9) -> 27 | I9: =G9/H9 -> 1.3611111 | J9: =_xlfn.DAYS(A9,B9) -> 217 | K9: =IFERROR(WORKDAY($A9, ROUNDUP(MAX(0, _xlfn.DAYS($A9, $B9)) / $I$40, 0),Sheet2!$A$2:$A$21),"") -> 46162 | L9: =A9*1.00474635070856 -> 46146.995 | M9: BPD LTC Fingerprint Call Calculator
A10: 45930 | B10: 45712 | D10: 0.25 | E10: =IF(A10="","",NETWORKDAYS(A9,A10,Sheet2!$A$2:$A$21)-1) -> 1 | F10: =D10/E10 -> 0.25 | G10: =SUM($D$3:D10) -> 37 | H10: =SUM($E$3:E10) -> 28 | I10: =G10/H10 -> 1.3214286 | J10: =_xlfn.DAYS(A10,B10) -> 218 | K10: =IFERROR(WORKDAY($A10, ROUNDUP(MAX(0, _xlfn.DAYS($A10, $B10)) / $I$40, 0),Sheet2!$A$2:$A$21),"") -> 46164 | L10: =A10*1.00474635070856 -> 46148
A11: 45931 | B11: 45716 | D11: =IF(B11="","",B11-B10) -> 4 | E11: =IF(A11="","",NETWORKDAYS(A10,A11,Sheet2!$A$2:$A$21)-1) -> 1 | F11: =D11/E11 -> 4 | G11: =SUM($D$3:D11) -> 41 | H11: =SUM($E$3:E11) -> 29 | I11: =G11/H11 -> 1.4137931 | J11: =_xlfn.DAYS(A11,B11) -> 215 | K11: =IFERROR(WORKDAY($A11, ROUNDUP(MAX(0, _xlfn.DAYS($A11, $B11)) / $I$40, 0),Sheet2!$A$2:$A$21),"") -> 46163 | L11: =A11*1.00474635070856 -> 46149.005 | N11: Enter Date Your Submitted your LTC Application:
A12: 45937 | B12: 45718 | D12: =IF(B12="","",B12-B11) -> 2 | E12: =IF(A12="","",NETWORKDAYS(A11,A12,Sheet2!$A$2:$A$21)-1) -> 4 | F12: =D12/E12 -> 0.5 | G12: =SUM($D$3:D12) -> 43 | H12: =SUM($E$3:E12) -> 33 | I12: =G12/H12 -> 1.3030303 | J12: =_xlfn.DAYS(A12,B12) -> 219 | K12: =IFERROR(WORKDAY($A12, ROUNDUP(MAX(0, _xlfn.DAYS($A12, $B12)) / $I$40, 0),Sheet2!$A$2:$A$21),"") -> 46175 | L12: =A12*1.00474635070856 -> 46155.033 | N12: 45828
A13: 45945 | B13: 45725 | D13: =IF(B13="","",B13-B12) -> 7 | E13: =IF(A13="","",NETWORKDAYS(A12,A13,Sheet2!$A$2:$A$21)-1) -> 5 | F13: =D13/E13 -> 1.4 | G13: =SUM($D$3:D13) -> 50 | H13: =SUM($E$3:E13) -> 38 | I13: =G13/H13 -> 1.3157895 | J13: =_xlfn.DAYS(A13,B13) -> 220 | K13: =IFERROR(WORKDAY($A13, ROUNDUP(MAX(0, _xlfn.DAYS($A13, $B13)) / $I$40, 0),Sheet2!$A$2:$A$21),"") -> 46183 | L13: =A13*1.00474635070856 -> 46163.071 | N13: .
A14: 45958 | B14: 45739 | D14: =IF(B14="","",B14-B13) -> 14 | E14: =IF(A14="","",NETWORKDAYS(A13,A14,Sheet2!$A$2:$A$21)-1) -> 9 | F14: =D14/E14 -> 1.5555556 | G14: =SUM($D$3:D14) -> 64 | H14: =SUM($E$3:E14) -> 47 | I14: =G14/H14 -> 1.3617021 | J14: =_xlfn.DAYS(A14,B14) -> 219 | K14: =IFERROR(WORKDAY($A14, ROUNDUP(MAX(0, _xlfn.DAYS($A14, $B14)) / $I$40, 0),Sheet2!$A$2:$A$21),"") -> 46195 | L14: =A14*1.00474635070856 -> 46176.133 | M14: Expected Date you will be called to schedule your fingerprinting appt:
A15: 45968 | B15: 45746 | D15: =IF(B15="","",B15-B14) -> 7 | E15: =IF(A15="","",NETWORKDAYS(A14,A15,Sheet2!$A$2:$A$21)-1) -> 8 | F15: =D15/E15 -> 0.875 | G15: =SUM($D$3:D15) -> 71 | H15: =SUM($E$3:E15) -> 55 | I15: =G15/H15 -> 1.2909091 | J15: =_xlfn.DAYS(A15,B15) -> 222 | K15: =IFERROR(WORKDAY($A15, ROUNDUP(MAX(0, _xlfn.DAYS($A15, $B15)) / $I$40, 0),Sheet2!$A$2:$A$21),"") -> 46210 | L15: =A15*1.00474635070856 -> 46186.18
A16: 45971 | B16: 45752 | D16: =IF(B16="","",B16-B15) -> 6 | E16: =IF(A16="","",NETWORKDAYS(A15,A16,Sheet2!$A$2:$A$21)-1) -> 1 | F16: =D16/E16 -> 6 | G16: =SUM($D$3:D16) -> 77 | H16: =SUM($E$3:E16) -> 56 | I16: =G16/H16 -> 1.375 | J16: =_xlfn.DAYS(A16,B16) -> 219 | K16: =IFERROR(WORKDAY($A16, ROUNDUP(MAX(0, _xlfn.DAYS($A16, $B16)) / $I$40, 0),Sheet2!$A$2:$A$21),"") -> 46209 | L16: =A16*1.00474635070856 -> 46189.194 | N16: =(F92*N12)+F93 -> 46055.991
A17: 45973 | B17: 45753 | D17: =IF(B17="","",B17-B16) -> 1 | E17: =IF(A17="","",NETWORKDAYS(A16,A17,Sheet2!$A$2:$A$21)-1) -> 1 | F17: =D17/E17 -> 1 | G17: =SUM($D$3:D17) -> 78 | H17: =SUM($E$3:E17) -> 57 | I17: =G17/H17 -> 1.3684211 | J17: =_xlfn.DAYS(A17,B17) -> 220 | K17: =IFERROR(WORKDAY($A17, ROUNDUP(MAX(0, _xlfn.DAYS($A17, $B17)) / $I$40, 0),Sheet2!$A$2:$A$21),"") -> 46211 | L17: =A17*1.00474635070856 -> 46191.204 | N17: (+-7 days)
A18: 45975 | B18: 45755 | D18: =IF(B18="","",B18-B17) -> 2 | E18: =IF(A18="","",NETWORKDAYS(A17,A18,Sheet2!$A$2:$A$21)-1) -> 2 | F18: =D18/E18 -> 1 | G18: =SUM($D$3:D18) -> 80 | H18: =SUM($E$3:E18) -> 59 | I18: =G18/H18 -> 1.3559322 | J18: =_xlfn.DAYS(A18,B18) -> 220 | K18: =IFERROR(WORKDAY($A18, ROUNDUP(MAX(0, _xlfn.DAYS($A18, $B18)) / $I$40, 0),Sheet2!$A$2:$A$21),"") -> 46213 | L18: =A18*1.00474635070856 -> 46193.213
A19: 45985 | B19: 45764 | D19: =IF(B19="","",B19-B18) -> 9 | E19: =IF(A19="","",NETWORKDAYS(A18,A19,Sheet2!$A$2:$A$21)-1) -> 6 | F19: =D19/E19 -> 1.5 | G19: =SUM($D$3:D19) -> 89 | H19: =SUM($E$3:E19) -> 65 | I19: =G19/H19 -> 1.3692308 | J19: =_xlfn.DAYS(A19,B19) -> 221 | K19: =IFERROR(WORKDAY($A19, ROUNDUP(MAX(0, _xlfn.DAYS($A19, $B19)) / $I$40, 0),Sheet2!$A$2:$A$21),"") -> 46223 | L19: =A19*1.00474635070856 -> 46203.261 | M19: **Add ~4-6 weeks to your expected call date to estimate when you'll have your license in hand. If you don't get your license by then, please call them and ask, as they might have sent it to the wrong address, lost it, or had it shipped to themselves instead of to you.**
A20: 46021 | B20: 45797 | D20: =IF(B20="","",B20-B19) -> 33 | E20: =IF(A20="","",NETWORKDAYS(A19,A20,Sheet2!$A$2:$A$21)-1) -> 24 | F20: =D20/E20 -> 1.375 | G20: =SUM($D$3:D20) -> 122 | H20: =SUM($E$3:E20) -> 89 | I20: =G20/H20 -> 1.3707865 | J20: =_xlfn.DAYS(A20,B20) -> 224 | K20: =IFERROR(WORKDAY($A20, ROUNDUP(MAX(0, _xlfn.DAYS($A20, $B20)) / $I$40, 0),Sheet2!$A$2:$A$21),"") -> 46260 | L20: =A20*1.00474635070856 -> 46239.432
A21: 46056 | B21: 45822 | C21: 46085 | D21: =IF(B21="","",B21-B20) -> 25 | E21: =IF(A21="","",NETWORKDAYS(A20,A21,Sheet2!$A$2:$A$21)-1) -> 23 | F21: =D21/E21 -> 1.0869565 | G21: =SUM($D$3:D21) -> 147 | H21: =SUM($E$3:E21) -> 112 | I21: =G21/H21 -> 1.3125 | J21: =_xlfn.DAYS(A21,B21) -> 234 | K21: =IFERROR(WORKDAY($A21, ROUNDUP(MAX(0, _xlfn.DAYS($A21, $B21)) / $I$40, 0),Sheet2!$A$2:$A$21),"") -> 46303 | L21: =A21*1.00474635070856 -> 46274.598
A22: 46058 | B22: 45831 | D22: =IF(B22="","",B22-B21) -> 9 | E22: =IF(A22="","",NETWORKDAYS(A21,A22,Sheet2!$A$2:$A$21)-1) -> 2 | F22: =D22/E22 -> 4.5 | G22: =SUM($D$3:D22) -> 156 | H22: =SUM($E$3:E22) -> 114 | I22: =G22/H22 -> 1.3684211 | J22: =_xlfn.DAYS(A22,B22) -> 227 | K22: =IFERROR(WORKDAY($A23, ROUNDUP(MAX(0, _xlfn.DAYS($A23, $B23)) / $I$40, 0),Sheet2!$A$2:$A$21),"") -> 46314 | L22: =A23*1.00474635070856 -> 46284.645
A23: 46066 | B23: 45834 | C23: 46091 | D23: =IF(B23="","",B23-B22) -> 3 | E23: =IF(A23="","",NETWORKDAYS(A22,A23,Sheet2!$A$2:$A$21)-1) -> 6 | F23: =D23/E23 -> 0.5 | G23: =SUM($D$3:D23) -> 159 | H23: =SUM($E$3:E23) -> 120 | I23: =G23/H23 -> 1.325 | J23: =_xlfn.DAYS(A23,B23) -> 232 | K23: =IFERROR(WORKDAY($A24, ROUNDUP(MAX(0, _xlfn.DAYS($A24, $B24)) / $I$40, 0),Sheet2!$A$2:$A$21),"") -> 46329 | L23: =A24*1.00474635070856 -> 46298.712
A24: 46080 | B24: 45846 | D24: =IF(B24="","",B24-B23) -> 12 | E24: =IF(A24="","",NETWORKDAYS(A23,A24,Sheet2!$A$2:$A$21)-1) -> 9 | F24: =D24/E24 -> 1.3333333 | G24: =SUM($D$3:D24) -> 171 | H24: =SUM($E$3:E24) -> 129 | I24: =G24/H24 -> 1.3255814 | J24: =_xlfn.DAYS(A24,B24) -> 234 | K24: =IFERROR(WORKDAY($A25, ROUNDUP(MAX(0, _xlfn.DAYS($A25, $B25)) / $I$40, 0),Sheet2!$A$2:$A$21),"") -> 46332 | L24: =A25*1.00474635070856 -> 46309.764
A25: 46091 | B25: 45862 | D25: =IF(B25="","",B25-B24) -> 16 | E25: =IF(A25="","",NETWORKDAYS(A24,A25,Sheet2!$A$2:$A$21)-1) -> 7 | F25: =D25/E25 -> 2.2857143 | G25: =SUM($D$3:D25) -> 187 | H25: =SUM($E$3:E25) -> 136 | I25: =G25/H25 -> 1.375 | J25: =_xlfn.DAYS(A25,B25) -> 229 | K25: =IFERROR(WORKDAY($A25, ROUNDUP(MAX(0, _xlfn.DAYS($A25, $B25)) / $I$40, 0),Sheet2!$A$2:$A$21),"") -> 46332 | L25: =A25*1.00474635070856 -> 46309.764
A26: 46093 | B26: 45864 | D26: =IF(B26="","",B26-B25) -> 2 | E26: =IF(A26="","",NETWORKDAYS(A25,A26,Sheet2!$A$2:$A$21)-1) -> 2 | F26: =D26/E26 -> 1 | G26: =SUM($D$3:D26) -> 189 | H26: =SUM($E$3:E26) -> 138 | I26: =G26/H26 -> 1.3695652 | J26: =_xlfn.DAYS(A26,B26) -> 229 | K26: =IFERROR(WORKDAY($A26, ROUNDUP(MAX(0, _xlfn.DAYS($A26, $B26)) / $I$40, 0),Sheet2!$A$2:$A$21),"") -> 46336 | L26: =A26*1.00474635070856 -> 46311.774
A27: 46099 | B27: 45871 | D27: =IF(B27="","",B27-B26) -> 7 | E27: =IF(A27="","",NETWORKDAYS(A26,A27,Sheet2!$A$2:$A$21)-1) -> 4 | F27: =D27/E27 -> 1.75 | G27: =SUM($D$3:D27) -> 196 | H27: =SUM($E$3:E27) -> 142 | I27: =G27/H27 -> 1.3802817 | J27: =_xlfn.DAYS(A27,B27) -> 228 | K27: =IFERROR(WORKDAY($A27, ROUNDUP(MAX(0, _xlfn.DAYS($A27, $B27)) / $I$40, 0),Sheet2!$A$2:$A$21),"") -> 46342 | L27: =A27*1.00474635070856 -> 46317.802
D28: =IF(B28="","",B28-B27) | E28: =IF(A28="","",NETWORKDAYS(A27,A28,Sheet2!$A$2:$A$21)-1) | F28: =D28/E28 -> #VALUE! | G28: =SUM($D$3:D28) -> 196 | H28: =SUM($E$3:E28) -> 142 | I28: =G28/H28 -> 1.3802817 | J28: =_xlfn.DAYS(A28,B28) -> 0 | K28: =IFERROR(WORKDAY($A28, ROUNDUP(MAX(0, _xlfn.DAYS($A28, $B28)) / $I$40, 0),Sheet2!$A$2:$A$21),"") -> 0 | L28: =A28*1.00474635070856 -> 0
D29: =IF(B29="","",B29-B28) | E29: =IF(A29="","",NETWORKDAYS(A28,A29,Sheet2!$A$2:$A$21)-1) | F29: =D29/E29 -> #VALUE! | G29: =SUM($D$3:D29) -> 196 | H29: =SUM($E$3:E29) -> 142 | I29: =G29/H29 -> 1.3802817 | J29: =_xlfn.DAYS(A29,B29) -> 0 | K29: =IFERROR(WORKDAY($A29, ROUNDUP(MAX(0, _xlfn.DAYS($A29, $B29)) / $I$40, 0),Sheet2!$A$2:$A$21),"") -> 0 | L29: =A29*1.00474635070856 -> 0
D30: =IF(B30="","",B30-B29) | E30: =IF(A30="","",NETWORKDAYS(A29,A30,Sheet2!$A$2:$A$21)-1) | F30: =D30/E30 -> #VALUE! | G30: =SUM($D$3:D30) -> 196 | H30: =SUM($E$3:E30) -> 142 | I30: =G30/H30 -> 1.3802817 | J30: =_xlfn.DAYS(A30,B30) -> 0 | K30: =IFERROR(WORKDAY($A30, ROUNDUP(MAX(0, _xlfn.DAYS($A30, $B30)) / $I$40, 0),Sheet2!$A$2:$A$21),"") -> 0 | L30: =A30*1.00474635070856 -> 0
D31: =IF(B31="","",B31-B30) | E31: =IF(A31="","",NETWORKDAYS(A30,A31,Sheet2!$A$2:$A$21)-1) | F31: =D31/E31 -> #VALUE! | G31: =SUM($D$3:D31) -> 196 | H31: =SUM($E$3:E31) -> 142 | I31: =G31/H31 -> 1.3802817 | J31: =_xlfn.DAYS(A31,B31) -> 0 | K31: =IFERROR(WORKDAY($A31, ROUNDUP(MAX(0, _xlfn.DAYS($A31, $B31)) / $I$40, 0),Sheet2!$A$2:$A$21),"") -> 0 | L31: =A31*1.00474635070856 -> 0
D32: =IF(B32="","",B32-B31) | E32: =IF(A32="","",NETWORKDAYS(A31,A32,Sheet2!$A$2:$A$21)-1) | F32: =D32/E32 -> #VALUE! | G32: =SUM($D$3:D32) -> 196 | H32: =SUM($E$3:E32) -> 142 | I32: =G32/H32 -> 1.3802817 | J32: =_xlfn.DAYS(A32,B32) -> 0 | K32: =IFERROR(WORKDAY($A32, ROUNDUP(MAX(0, _xlfn.DAYS($A32, $B32)) / $I$40, 0),Sheet2!$A$2:$A$21),"") -> 0 | L32: =A32*1.00474635070856 -> 0
D33: =IF(B33="","",B33-B32) | E33: =IF(A33="","",NETWORKDAYS(A32,A33,Sheet2!$A$2:$A$21)-1) | F33: =D33/E33 -> #VALUE! | G33: =SUM($D$3:D33) -> 196 | H33: =SUM($E$3:E33) -> 142 | I33: =G33/H33 -> 1.3802817 | J33: =_xlfn.DAYS(A33,B33) -> 0 | K33: =IFERROR(WORKDAY($A33, ROUNDUP(MAX(0, _xlfn.DAYS($A33, $B33)) / $I$40, 0),Sheet2!$A$2:$A$21),"") -> 0 | L33: =A33*1.00474635070856 -> 0
D34: =IF(B34="","",B34-B33) | E34: =IF(A34="","",NETWORKDAYS(A33,A34,Sheet2!$A$2:$A$21)-1) | F34: =D34/E34 -> #VALUE! | G34: =SUM($D$3:D34) -> 196 | H34: =SUM($E$3:E34) -> 142 | I34: =G34/H34 -> 1.3802817 | J34: =_xlfn.DAYS(A34,B34) -> 0 | K34: =IFERROR(WORKDAY($A34, ROUNDUP(MAX(0, _xlfn.DAYS($A34, $B34)) / $I$40, 0),Sheet2!$A$2:$A$21),"") -> 0 | L34: =A34*1.00474635070856 -> 0
D35: =IF(B35="","",B35-B34) | E35: =IF(A35="","",NETWORKDAYS(A34,A35,Sheet2!$A$2:$A$21)-1) | F35: =D35/E35 -> #VALUE! | G35: =SUM($D$3:D35) -> 196 | H35: =SUM($E$3:E35) -> 142 | I35: =G35/H35 -> 1.3802817 | J35: =_xlfn.DAYS(A35,B35) -> 0 | K35: =IFERROR(WORKDAY($A35, ROUNDUP(MAX(0, _xlfn.DAYS($A35, $B35)) / $I$40, 0),Sheet2!$A$2:$A$21),"") -> 0 | L35: =A35*1.00474635070856 -> 0
D36: =IF(B36="","",B36-B35) | E36: =IF(A36="","",NETWORKDAYS(A35,A36,Sheet2!$A$2:$A$21)-1) | F36: =D36/E36 -> #VALUE! | G36: =SUM($D$3:D36) -> 196 | H36: =SUM($E$3:E36) -> 142 | I36: =G36/H36 -> 1.3802817 | J36: =_xlfn.DAYS(A36,B36) -> 0 | K36: =IFERROR(WORKDAY($A36, ROUNDUP(MAX(0, _xlfn.DAYS($A36, $B36)) / $I$40, 0),Sheet2!$A$2:$A$21),"") -> 0 | L36: =A36*1.00474635070856 -> 0
D37: =IF(B37="","",B37-B36) | E37: =IF(A37="","",NETWORKDAYS(A36,A37,Sheet2!$A$2:$A$21)-1) | F37: =D37/E37 -> #VALUE! | G37: =SUM($D$3:D37) -> 196 | H37: =SUM($E$3:E37) -> 142 | I37: =G37/H37 -> 1.3802817 | J37: =_xlfn.DAYS(A37,B37) -> 0 | K37: =IFERROR(WORKDAY($A37, ROUNDUP(MAX(0, _xlfn.DAYS($A37, $B37)) / $I$40, 0),Sheet2!$A$2:$A$21),"") -> 0 | L37: =A37*1.00474635070856 -> 0
D38: =IF(B38="","",B38-B37) | E38: =IF(A38="","",NETWORKDAYS(A37,A38,Sheet2!$A$2:$A$21)-1) | F38: =D38/E38 -> #VALUE! | G38: =SUM($D$3:D38) -> 196 | H38: =SUM($E$3:E38) -> 142 | I38: =G38/H38 -> 1.3802817 | J38: =_xlfn.DAYS(A38,B38) -> 0 | K38: =IFERROR(WORKDAY($A38, ROUNDUP(MAX(0, _xlfn.DAYS($A38, $B38)) / $I$40, 0),Sheet2!$A$2:$A$21),"") -> 0 | L38: =A38*1.00474635070856 -> 0
D39: =IF(B39="","",B39-B38) | E39: =IF(A39="","",NETWORKDAYS(A38,A39,Sheet2!$A$2:$A$21)-1) | F39: =D39/E39 -> #VALUE! | G39: =SUM($D$3:D39) -> 196 | H39: =SUM($E$3:E39) -> 142 | I39: =G39/H39 -> 1.3802817 | J39: =_xlfn.DAYS(A39,B39) -> 0 | K39: =IFERROR(WORKDAY($A39, ROUNDUP(MAX(0, _xlfn.DAYS($A39, $B39)) / $I$40, 0),Sheet2!$A$2:$A$21),"") -> 0 | L39: =A39*1.00474635070856 -> 0
A40: Averages: | D40: =AVERAGE(D3:D27) -> 7.84 | E40: =AVERAGE(E3:E27) -> 5.68 | F40: =AVERAGE(F3:F27) -> 1.6571291 | G40: =AVERAGE(G3:G27) -> 86.65 | H40: =AVERAGE(H3:H27) -> 63.88 | I40: =AVERAGE(I3:I27) -> 1.3575635 | J40: =AVERAGE(J2:J27) -> 221.03846
...

Sheet Historical
A1: 1.1666667
A2: 1.2941176
A3: 1.4761905
A4: 1.4347826
A5: 1.5
A6: 1.4038462
A7: 1.3611111
A8: 1.3214286
A9: 1.4137931
A10: 1.3030303
A11: 1.3157895
A12: 1.3617021
... A18: 1.3707865

Sheet Inputs
B2: 224
B3: 46021

Sheet Simulation
A1: Sim # | B1: Sampled Pace | C1: Days to Process | D1: Processing Date
A2: =ROW()-1 -> 1 | B2: {=INDEX(Historical!$A$1:$A$18, RANDBETWEEN(1, COUNTA(Historical!$A$1:$A$18)))} -> 1.3157895 | C2: =Inputs!$B$2/B2 -> 170.24 | D2: =WORKDAY(Inputs!$B$3, ROUND(C2, 0),Sheet2!$A$2:$A$21) -> 46266 | F2: =MIN(D2:D2147) -> 46237 | G2: 46237 | H2: =COUNTIF(D$2:D$2147,G2) -> 129 | I2: =H2/COUNTA(D$2:D$2147) -> 0.060111836 | J2: =SUM($I$2:I2) -> 0.060111836 | K2: =_xlfn.PERCENTILE.INC(D$2:D$2147,0.1) -> 46240 | R2: 46237 | S2: 126 | T2: 0.058713886 | U2: 0.058713886
A3: =ROW()-1 -> 2 | B3: {=INDEX(Historical!$A$1:$A$18, RANDBETWEEN(1, COUNTA(Historical!$A$1:$A$18)))} -> 1.3692308 | C3: =Inputs!$B$2/B3 -> 163.59551 | D3: =WORKDAY(Inputs!$B$3, ROUND(C3, 0),Sheet2!$A$2:$A$21) -> 46258 | F3: =MAX(D2:D2147) -> 46297 | G3: =WORKDAY(G2,1,Sheet2!$A$2:$A$21) -> 46238 | H3: =COUNTIF(D$2:D$2147,G3) -> 0 | I3: =H3/COUNTA(D$2:D$2147) -> 0 | J3: =SUM($I$2:I3) -> 0.060111836 | K3: =_xlfn.PERCENTILE.INC(D$2:D$2147,0.9) -> 46273 | N3: =_xlfn.PERCENTILE.INC(D:D,0.4) -> 46258 | R3: 46240 | S3: 117 | T3: 0.054520037 | U3: 0.11323392
A4: =ROW()-1 -> 3 | B4: {=INDEX(Historical!$A$1:$A$18, RANDBETWEEN(1, COUNTA(Historical!$A$1:$A$18)))} -> 1.2909091 | C4: =Inputs!$B$2/B4 -> 173.52113 | D4: =WORKDAY(Inputs!$B$3, ROUND(C4, 0),Sheet2!$A$2:$A$21) -> 46273 | G4: =WORKDAY(G3,1,Sheet2!$A$2:$A$21) -> 46239 | H4: =COUNTIF(D$2:D$2147,G4) -> 0 | I4: =H4/COUNTA(D$2:D$2147) -> 0 | J4: =SUM($I$2:I4) -> 0.060111836 | N4: =_xlfn.PERCENTILE.INC(D:D,0.5) -> 46259 | O4: =MEDIAN(D2:D2147) -> 46259 | R4: 46246 | S4: 120 | T4: 0.055917987 | U4: 0.16915191
A5: =ROW()-1 -> 4 | B5: {=INDEX(Historical!$A$1:$A$18, RANDBETWEEN(1, COUNTA(Historical!$A$1:$A$18)))} -> 1.3559322 | C5: =Inputs!$B$2/B5 -> 165.2 | D5: =WORKDAY(Inputs!$B$3, ROUND(C5, 0),Sheet2!$A$2:$A$21) -> 46259 | G5: =WORKDAY(G4,1,Sheet2!$A$2:$A$21) -> 46240 | H5: =COUNTIF(D$2:D$2147,G5) -> 110 | I5: =H5/COUNTA(D$2:D$2147) -> 0.051258155 | J5: =SUM($I$2:I5) -> 0.11136999 | K5: =MEDIAN(D:D) -> 46259 | N5: =_xlfn.PERCENTILE.INC(D:D, 0.8) -> 46268 | R5: 46248 | S5: 122 | T5: 0.056849953 | U5: 0.22600186
A6: =ROW()-1 -> 5 | B6: {=INDEX(Historical!$A$1:$A$18, RANDBETWEEN(1, COUNTA(Historical!$A$1:$A$18)))} -> 1.3157895 | C6: =Inputs!$B$2/B6 -> 170.24 | D6: =WORKDAY(Inputs!$B$3, ROUND(C6, 0),Sheet2!$A$2:$A$21) -> 46266 | G6: =WORKDAY(G5,1,Sheet2!$A$2:$A$21) -> 46241 | H6: =COUNTIF(D$2:D$2147,G6) -> 0 | I6: =H6/COUNTA(D$2:D$2147) -> 0 | J6: =SUM($I$2:I6) -> 0.11136999 | N6: =_xlfn.PERCENTILE.INC(D:D, 0.95) -> 46297 | R6: 46252 | S6: 120 | T6: 0.055917987 | U6: 0.28191985
A7: =ROW()-1 -> 6 | B7: {=INDEX(Historical!$A$1:$A$18, RANDBETWEEN(1, COUNTA(Historical!$A$1:$A$18)))} -> 1.4038462 | C7: =Inputs!$B$2/B7 -> 159.56164 | D7: =WORKDAY(Inputs!$B$3, ROUND(C7, 0),Sheet2!$A$2:$A$21) -> 46252 | G7: =WORKDAY(G6,1,Sheet2!$A$2:$A$21) -> 46244 | H7: =COUNTIF(D$2:D$2147,G7) -> 0 | I7: =H7/COUNTA(D$2:D$2147) -> 0 | J7: =SUM($I$2:I7) -> 0.11136999 | R7: 46255 | S7: 221 | T7: 0.10298229 | U7: 0.38490214
A8: =ROW()-1 -> 7 | B8: {=INDEX(Historical!$A$1:$A$18, RANDBETWEEN(1, COUNTA(Historical!$A$1:$A$18)))} -> 1.3214286 | C8: =Inputs!$B$2/B8 -> 169.51351 | D8: =WORKDAY(Inputs!$B$3, ROUND(C8, 0),Sheet2!$A$2:$A$21) -> 46266 | G8: =WORKDAY(G7,1,Sheet2!$A$2:$A$21) -> 46245 | H8: =COUNTIF(D$2:D$2147,G8) -> 0 | I8: =H8/COUNTA(D$2:D$2147) -> 0 | J8: =SUM($I$2:I8) -> 0.11136999 | R8: 46258 | S8: 236 | T8: 0.10997204 | U8: 0.49487418
A9: =ROW()-1 -> 8 | B9: {=INDEX(Historical!$A$1:$A$18, RANDBETWEEN(1, COUNTA(Historical!$A$1:$A$18)))} -> 1.4761905 | C9: =Inputs!$B$2/B9 -> 151.74194 | D9: =WORKDAY(Inputs!$B$3, ROUND(C9, 0),Sheet2!$A$2:$A$21) -> 46240 | G9: =WORKDAY(G8,1,Sheet2!$A$2:$A$21) -> 46246 | H9: =COUNTIF(D$2:D$2147,G9) -> 123 | I9: =H9/COUNTA(D$2:D$2147) -> 0.057315937 | J9: =SUM($I$2:I9) -> 0.16868593 | R9: 46259 | S9: 373 | T9: 0.17381174 | U9: 0.66868593
A10: =ROW()-1 -> 9 | B10: {=INDEX(Historical!$A$1:$A$18, RANDBETWEEN(1, COUNTA(Historical!$A$1:$A$18)))} -> 1.4038462 | C10: =Inputs!$B$2/B10 -> 159.56164 | D10: =WORKDAY(Inputs!$B$3, ROUND(C10, 0),Sheet2!$A$2:$A$21) -> 46252 | G10: =WORKDAY(G9,1,Sheet2!$A$2:$A$21) -> 46247 | H10: =COUNTIF(D$2:D$2147,G10) -> 0 | I10: =H10/COUNTA(D$2:D$2147) -> 0 | J10: =SUM($I$2:I10) -> 0.16868593 | R10: 46266 | S10: 235 | T10: 0.10950606 | U10: 0.77819199
A11: =ROW()-1 -> 10 | B11: {=INDEX(Historical!$A$1:$A$18, RANDBETWEEN(1, COUNTA(Historical!$A$1:$A$18)))} -> 1.3707865 | C11: =Inputs!$B$2/B11 -> 163.40984 | D11: =WORKDAY(Inputs!$B$3, ROUND(C11, 0),Sheet2!$A$2:$A$21) -> 46255 | G11: =WORKDAY(G10,1,Sheet2!$A$2:$A$21) -> 46248 | H11: =COUNTIF(D$2:D$2147,G11) -> 115 | I11: =H11/COUNTA(D$2:D$2147) -> 0.053588071 | J11: =SUM($I$2:I11) -> 0.222274 | R11: 46268 | S11: 118 | T11: 0.054986021 | U11: 0.83317801
A12: =ROW()-1 -> 11 | B12: {=INDEX(Historical!$A$1:$A$18, RANDBETWEEN(1, COUNTA(Historical!$A$1:$A$18)))} -> 1.3707865 | C12: =Inputs!$B$2/B12 -> 163.40984 | D12: =WORKDAY(Inputs!$B$3, ROUND(C12, 0),Sheet2!$A$2:$A$21) -> 46255 | G12: =WORKDAY(G11,1,Sheet2!$A$2:$A$21) -> 46251 | H12: =COUNTIF(D$2:D$2147,G12) -> 0 | I12: =H12/COUNTA(D$2:D$2147) -> 0 | J12: =SUM($I$2:I12) -> 0.222274 | R12: 46269 | S12: 106 | T12: 0.049394222 | U12: 0.88257223
A13: =ROW()-1 -> 12 | B13: {=INDEX(Historical!$A$1:$A$18, RANDBETWEEN(1, COUNTA(Historical!$A$1:$A$18)))} -> 1.4761905 | C13: =Inputs!$B$2/B13 -> 151.74194 | D13: =WORKDAY(Inputs!$B$3, ROUND(C13, 0),Sheet2!$A$2:$A$21) -> 46240 | G13: =WORKDAY(G12,1,Sheet2!$A$2:$A$21) -> 46252 | H13: =COUNTIF(D$2:D$2147,G13) -> 108 | I13: =H13/COUNTA(D$2:D$2147) -> 0.050326188 | J13: =SUM($I$2:I13) -> 0.27260019 | R13: 46273 | S13: 128 | T13: 0.059645853 | U13: 0.94221808
A14: =ROW()-1 -> 13 | B14: {=INDEX(Historical!$A$1:$A$18, RANDBETWEEN(1, COUNTA(Historical!$A$1:$A$18)))} -> 1.4137931 | C14: =Inputs!$B$2/B14 -> 158.43902 | D14: =WORKDAY(Inputs!$B$3, ROUND(C14, 0),Sheet2!$A$2:$A$21) -> 46248 | G14: =WORKDAY(G13,1,Sheet2!$A$2:$A$21) -> 46253 | H14: =COUNTIF(D$2:D$2147,G14) -> 0 | I14: =H14/COUNTA(D$2:D$2147) -> 0 | J14: =SUM($I$2:I14) -> 0.27260019 | R14: 46297 | S14: 124 | T14: 0.05778192 | U14: 1
A15: =ROW()-1 -> 14 | B15: {=INDEX(Historical!$A$1:$A$18, RANDBETWEEN(1, COUNTA(Historical!$A$1:$A$18)))} -> 1.2941176 | C15: =Inputs!$B$2/B15 -> 173.09091 | D15: =WORKDAY(Inputs!$B$3, ROUND(C15, 0),Sheet2!$A$2:$A$21) -> 46269 | G15: =WORKDAY(G14,1,Sheet2!$A$2:$A$21) -> 46254 | H15: =COUNTIF(D$2:D$2147,G15) -> 0 | I15: =H15/COUNTA(D$2:D$2147) -> 0 | J15: =SUM($I$2:I15) -> 0.27260019
A16: =ROW()-1 -> 15 | B16: {=INDEX(Historical!$A$1:$A$18, RANDBETWEEN(1, COUNTA(Historical!$A$1:$A$18)))} -> 1.4137931 | C16: =Inputs!$B$2/B16 -> 158.43902 | D16: =WORKDAY(Inputs!$B$3, ROUND(C16, 0),Sheet2!$A$2:$A$21) -> 46248 | G16: =WORKDAY(G15,1,Sheet2!$A$2:$A$21) -> 46255 | H16: =COUNTIF(D$2:D$2147,G16) -> 241 | I16: =H16/COUNTA(D$2:D$2147) -> 0.11230196 | J16: =SUM($I$2:I16) -> 0.38490214
A17: =ROW()-1 -> 16 | B17: {=INDEX(Historical!$A$1:$A$18, RANDBETWEEN(1, COUNTA(Historical!$A$1:$A$18)))} -> 1.2909091 | C17: =Inputs!$B$2/B17 -> 173.52113 | D17: =WORKDAY(Inputs!$B$3, ROUND(C17, 0),Sheet2!$A$2:$A$21) -> 46273 | G17: =WORKDAY(G16,1,Sheet2!$A$2:$A$21) -> 46258 | H17: =COUNTIF(D$2:D$2147,G17) -> 235 | I17: =H17/COUNTA(D$2:D$2147) -> 0.10950606 | J17: =SUM($I$2:I17) -> 0.4944082
A18: =ROW()-1 -> 17 | B18: {=INDEX(Historical!$A$1:$A$18, RANDBETWEEN(1, COUNTA(Historical!$A$1:$A$18)))} -> 1.3157895 | C18: =Inputs!$B$2/B18 -> 170.24 | D18: =WORKDAY(Inputs!$B$3, ROUND(C18, 0),Sheet2!$A$2:$A$21) -> 46266 | G18: =WORKDAY(G17,1,Sheet2!$A$2:$A$21) -> 46259 | H18: =COUNTIF(D$2:D$2147,G18) -> 360 | I18: =H18/COUNTA(D$2:D$2147) -> 0.16775396 | J18: =SUM($I$2:I18) -> 0.66216216
A19: =ROW()-1 -> 18 | B19: {=INDEX(Historical!$A$1:$A$18, RANDBETWEEN(1, COUNTA(Historical!$A$1:$A$18)))} -> 1.3684211 | C19: =Inputs!$B$2/B19 -> 163.69231 | D19: =WORKDAY(Inputs!$B$3, ROUND(C19, 0),Sheet2!$A$2:$A$21) -> 46258 | G19: =WORKDAY(G18,1,Sheet2!$A$2:$A$21) -> 46260 | H19: =COUNTIF(D$2:D$2147,G19) -> 0 | I19: =H19/COUNTA(D$2:D$2147) -> 0 | J19: =SUM($I$2:I19) -> 0.66216216
A20: =ROW()-1 -> 19 | B20: {=INDEX(Historical!$A$1:$A$18, RANDBETWEEN(1, COUNTA(Historical!$A$1:$A$18)))} -> 1.375 | C20: =Inputs!$B$2/B20 -> 162.90909 | D20: =WORKDAY(Inputs!$B$3, ROUND(C20, 0),Sheet2!$A$2:$A$21) -> 46255 | G20: =WORKDAY(G19,1,Sheet2!$A$2:$A$21) -> 46261 | H20: =COUNTIF(D$2:D$2147,G20) -> 0 | I20: =H20/COUNTA(D$2:D$2147) -> 0 | J20: =SUM($I$2:I20) -> 0.66216216
A21: =ROW()-1 -> 20 | B21: {=INDEX(Historical!$A$1:$A$18, RANDBETWEEN(1, COUNTA(Historical!$A$1:$A$18)))} -> 1.4137931 | C21: =Inputs!$B$2/B21 -> 158.43902 | D21: =WORKDAY(Inputs!$B$3, ROUND(C21, 0),Sheet2!$A$2:$A$21) -> 46248 | G21: =WORKDAY(G20,1,Sheet2!$A$2:$A$21) -> 46262 | H21: =COUNTIF(D$2:D$2147,G21) -> 0 | I21: =H21/COUNTA(D$2:D$2147) -> 0 | J21: =SUM($I$2:I21) -> 0.66216216
A22: =ROW()-1 -> 21 | B22: {=INDEX(Historical!$A$1:$A$18, RANDBETWEEN(1, COUNTA(Historical!$A$1:$A$18)))} -> 1.3030303 | C22: =Inputs!$B$2/B22 -> 171.90698 | D22: =WORKDAY(Inputs!$B$3, ROUND(C22, 0),Sheet2!$A$2:$A$21) -> 46268 | G22: =WORKDAY(G21,1,Sheet2!$A$2:$A$21) -> 46265 | H22: =COUNTIF(D$2:D$2147,G22) -> 0 | I22: =H22/COUNTA(D$2:D$2147) -> 0 | J22: =SUM($I$2:I22) -> 0.66216216
A23: =ROW()-1 -> 22 | B23: {=INDEX(Historical!$A$1:$A$18, RANDBETWEEN(1, COUNTA(Historical!$A$1:$A$18)))} -> 1.4347826 | C23: =Inputs!$B$2/B23 -> 156.12121 | D23: =WORKDAY(Inputs!$B$3, ROUND(C23, 0),Sheet2!$A$2:$A$21) -> 46246 | G23: =WORKDAY(G22,1,Sheet2!$A$2:$A$21) -> 46266 | H23: =COUNTIF(D$2:D$2147,G23) -> 255 | I23: =H23/COUNTA(D$2:D$2147) -> 0.11882572 | J23: =SUM($I$2:I23) -> 0.78098788
A24: =ROW()-1 -> 23 | B24: {=INDEX(Historical!$A$1:$A$18, RANDBETWEEN(1, COUNTA(Historical!$A$1:$A$18)))} -> 1.3214286 | C24: =Inputs!$B$2/B24 -> 169.51351 | D24: =WORKDAY(Inputs!$B$3, ROUND(C24, 0),Sheet2!$A$2:$A$21) -> 46266 | G24: =WORKDAY(G23,1,Sheet2!$A$2:$A$21) -> 46267 | H24: =COUNTIF(D$2:D$2147,G24) -> 0 | I24: =H24/COUNTA(D$2:D$2147) -> 0 | J24: =SUM($I$2:I24) -> 0.78098788
A25: =ROW()-1 -> 24 | B25: {=INDEX(Historical!$A$1:$A$18, RANDBETWEEN(1, COUNTA(Historical!$A$1:$A$18)))} -> 1.3611111 | C25: =Inputs!$B$2/B25 -> 164.57143 | D25: =WORKDAY(Inputs!$B$3, ROUND(C25, 0),Sheet2!$A$2:$A$21) -> 46259 | G25: =WORKDAY(G24,1,Sheet2!$A$2:$A$21) -> 46268 | H25: =COUNTIF(D$2:D$2147,G25) -> 113 | I25: =H25/COUNTA(D$2:D$2147) -> 0.052656104 | J25: =SUM($I$2:I25) -> 0.83364399
A26: =ROW()-1 -> 25 | B26: {=INDEX(Historical!$A$1:$A$18, RANDBETWEEN(1, COUNTA(Historical!$A$1:$A$18)))} -> 1.5 | C26: =Inputs!$B$2/B26 -> 149.33333 | D26: =WORKDAY(Inputs!$B$3, ROUND(C26, 0),Sheet2!$A$2:$A$21) -> 46237 | G26: =WORKDAY(G25,1,Sheet2!$A$2:$A$21) -> 46269 | H26: =COUNTIF(D$2:D$2147,G26) -> 113 | I26: =H26/COUNTA(D$2:D$2147) -> 0.052656104 | J26: =SUM($I$2:I26) -> 0.88630009
A27: =ROW()-1 -> 26 | B27: {=INDEX(Historical!$A$1:$A$18, RANDBETWEEN(1, COUNTA(Historical!$A$1:$A$18)))} -> 1.3214286 | C27: =Inputs!$B$2/B27 -> 169.51351 | D27: =WORKDAY(Inputs!$B$3, ROUND(C27, 0),Sheet2!$A$2:$A$21) -> 46266 | G27: =WORKDAY(G26,1,Sheet2!$A$2:$A$21) -> 46273 | H27: =COUNTIF(D$2:D$2147,G27) -> 121 | I27: =H27/COUNTA(D$2:D$2147) -> 0.05638397 | J27: =SUM($I$2:I27) -> 0.94268406 | R27: =_xlfn.PERCENTILE.INC(D:D,0.28) -> 46255
A28: =ROW()-1 -> 27 | B28: {=INDEX(Historical!$A$1:$A$18, RANDBETWEEN(1, COUNTA(Historical!$A$1:$A$18)))} -> 1.3214286 | C28: =Inputs!$B$2/B28 -> 169.51351 | D28: =WORKDAY(Inputs!$B$3, ROUND(C28, 0),Sheet2!$A$2:$A$21) -> 46266 | G28: =WORKDAY(G27,1,Sheet2!$A$2:$A$21) -> 46274 | H28: =COUNTIF(D$2:D$2147,G28) -> 0 | I28: =H28/COUNTA(D$2:D$2147) -> 0 | J28: =SUM($I$2:I28) -> 0.94268406 | R28: =_xlfn.PERCENTILE.INC(D:D,0.8) -> 46268
A29: =ROW()-1 -> 28 | B29: {=INDEX(Historical!$A$1:$A$18, RANDBETWEEN(1, COUNTA(Historical!$A$1:$A$18)))} -> 1.1666667 | C29: =Inputs!$B$2/B29 -> 192 | D29: =WORKDAY(Inputs!$B$3, ROUND(C29, 0),Sheet2!$A$2:$A$21) -> 46297 | G29: =WORKDAY(G28,1,Sheet2!$A$2:$A$21) -> 46275 | H29: =COUNTIF(D$2:D$2147,G29) -> 0 | I29: =H29/COUNTA(D$2:D$2147) -> 0 | J29: =SUM($I$2:I29) -> 0.94268406
A30: =ROW()-1 -> 29 | B30: {=INDEX(Historical!$A$1:$A$18, RANDBETWEEN(1, COUNTA(Historical!$A$1:$A$18)))} -> 1.1666667 | C30: =Inputs!$B$2/B30 -> 192 | D30: =WORKDAY(Inputs!$B$3, ROUND(C30, 0),Sheet2!$A$2:$A$21) -> 46297 | G30: =WORKDAY(G29,1,Sheet2!$A$2:$A$21) -> 46276 | H30: =COUNTIF(D$2:D$2147,G30) -> 0 | I30: =H30/COUNTA(D$2:D$2147) -> 0 | J30: =SUM($I$2:I30) -> 0.94268406
A31: =ROW()-1 -> 30 | B31: {=INDEX(Historical!$A$1:$A$18, RANDBETWEEN(1, COUNTA(Historical!$A$1:$A$18)))} -> 1.4761905 | C31: =Inputs!$B$2/B31 -> 151.74194 | D31: =WORKDAY(Inputs!$B$3, ROUND(C31, 0),Sheet2!$A$2:$A$21) -> 46240 | G31: =WORKDAY(G30,1,Sheet2!$A$2:$A$21) -> 46279 | H31: =COUNTIF(D$2:D$2147,G31) -> 0 | I31: =H31/COUNTA(D$2:D$2147) -> 0 | J31: =SUM($I$2:I31) -> 0.94268406
A32: =ROW()-1 -> 31 | B32: {=INDEX(Historical!$A$1:$A$18, RANDBETWEEN(1, COUNTA(Historical!$A$1:$A$18)))} -> 1.2909091 | C32: =Inputs!$B$2/B32 -> 173.52113 | D32: =WORKDAY(Inputs!$B$3, ROUND(C32, 0),Sheet2!$A$2:$A$21) -> 46273 | G32: =WORKDAY(G31,1,Sheet2!$A$2:$A$21) -> 46280 | H32: =COUNTIF(D$2:D$2147,G32) -> 0 | I32: =H32/COUNTA(D$2:D$2147) -> 0 | J32: =SUM($I$2:I32) -> 0.94268406
A33: =ROW()-1 -> 32 | B33: {=INDEX(Historical!$A$1:$A$18, RANDBETWEEN(1, COUNTA(Historical!$A$1:$A$18)))} -> 1.3707865 | C33: =Inputs!$B$2/B33 -> 163.40984 | D33: =WORKDAY(Inputs!$B$3, ROUND(C33, 0),Sheet2!$A$2:$A$21) -> 46255 | G33: =WORKDAY(G32,1,Sheet2!$A$2:$A$21) -> 46281 | H33: =COUNTIF(D$2:D$2147,G33) -> 0 | I33: =H33/COUNTA(D$2:D$2147) -> 0 | J33: =SUM($I$2:I33) -> 0.94268406
A34: =ROW()-1 -> 33 | B34: {=INDEX(Historical!$A$1:$A$18, RANDBETWEEN(1, COUNTA(Historical!$A$1:$A$18)))} -> 1.3214286 | C34: =Inputs!$B$2/B34 -> 169.51351 | D34: =WORKDAY(Inputs!$B$3, ROUND(C34, 0),Sheet2!$A$2:$A$21) -> 46266 | G34: =WORKDAY(G33,1,Sheet2!$A$2:$A$21) -> 46282 | H34: =COUNTIF(D$2:D$2147,G34) -> 0 | I34: =H34/COUNTA(D$2:D$2147) -> 0 | J34: =SUM($I$2:I34) -> 0.94268406
A35: =ROW()-1 -> 34 | B35: {=INDEX(Historical!$A$1:$A$18, RANDBETWEEN(1, COUNTA(Historical!$A$1:$A$18)))} -> 1.3617021 | C35: =Inputs!$B$2/B35 -> 164.5 | D35: =WORKDAY(Inputs!$B$3, ROUND(C35, 0),Sheet2!$A$2:$A$21) -> 46259 | G35: =WORKDAY(G34,1,Sheet2!$A$2:$A$21) -> 46283 | H35: =COUNTIF(D$2:D$2147,G35) -> 0 | I35: =H35/COUNTA(D$2:D$2147) -> 0 | J35: =SUM($I$2:I35) -> 0.94268406
A36: =ROW()-1 -> 35 | B36: {=INDEX(Historical!$A$1:$A$18, RANDBETWEEN(1, COUNTA(Historical!$A$1:$A$18)))} -> 1.2909091 | C36: =Inputs!$B$2/B36 -> 173.52113 | D36: =WORKDAY(Inputs!$B$3, ROUND(C36, 0),Sheet2!$A$2:$A$21) -> 46273 | G36: =WORKDAY(G35,1,Sheet2!$A$2:$A$21) -> 46286 | H36: =COUNTIF(D$2:D$2147,G36) -> 0 | I36: =H36/COUNTA(D$2:D$2147) -> 0 | J36: =SUM($I$2:I36) -> 0.94268406
A37: =ROW()-1 -> 36 | B37: {=INDEX(Historical!$A$1:$A$18, RANDBETWEEN(1, COUNTA(Historical!$A$1:$A$18)))} -> 1.3692308 | C37: =Inputs!$B$2/B37 -> 163.59551 | D37: =WORKDAY(Inputs!$B$3, ROUND(C37, 0),Sheet2!$A$2:$A$21) -> 46258 | G37: =WORKDAY(G36,1,Sheet2!$A$2:$A$21) -> 46287 | H37: =COUNTIF(D$2:D$2147,G37) -> 0 | I37: =H37/COUNTA(D$2:D$2147) -> 0 | J37: =SUM($I$2:I37) -> 0.94268406
A38: =ROW()-1 -> 37 | B38: {=INDEX(Historical!$A$1:$A$18, RANDBETWEEN(1, COUNTA(Historical!$A$1:$A$18)))} -> 1.4347826 | C38: =Inputs!$B$2/B38 -> 156.12121 | D38: =WORKDAY(Inputs!$B$3, ROUND(C38, 0),Sheet2!$A$2:$A$21) -> 46246 | G38: =WORKDAY(G37,1,Sheet2!$A$2:$A$21) -> 46288 | H38: =COUNTIF(D$2:D$2147,G38) -> 0 | I38: =H38/COUNTA(D$2:D$2147) -> 0 | J38: =SUM($I$2:I38) -> 0.94268406
A39: =ROW()-1 -> 38 | B39: {=INDEX(Historical!$A$1:$A$18, RANDBETWEEN(1, COUNTA(Historical!$A$1:$A$18)))} -> 1.4137931 | C39: =Inputs!$B$2/B39 -> 158.43902 | D39: =WORKDAY(Inputs!$B$3, ROUND(C39, 0),Sheet2!$A$2:$A$21) -> 46248 | G39: =WORKDAY(G38,1,Sheet2!$A$2:$A$21) -> 46289 | H39: =COUNTIF(D$2:D$2147,G39) -> 0 | I39: =H39/COUNTA(D$2:D$2147) -> 0 | J39: =SUM($I$2:I39) -> 0.94268406
A40: =ROW()-1 -> 39 | B40: {=INDEX(Historical!$A$1:$A$18, RANDBETWEEN(1, COUNTA(Historical!$A$1:$A$18)))} -> 1.375 | C40: =Inputs!$B$2/B40 -> 162.90909 | D40: =WORKDAY(Inputs!$B$3, ROUND(C40, 0),Sheet2!$A$2:$A$21) -> 46255 | G40: =WORKDAY(G39,1,Sheet2!$A$2:$A$21) -> 46290 | H40: =COUNTIF(D$2:D$2147,G40) -> 0 | I40: =H40/COUNTA(D$2:D$2147) -> 0 | J40: =SUM($I$2:I40) -> 0.94268406
...

Sheet Sheet1
A1: Call Date | B1: Queue Date | C1: App-Days Advanced | D1: Workdays Elapsed | E1: Pace (app-days/ workdays) | F1: Cumulative App-Days Completed | G1: Cumulative Work-Days Completed | H1: Cumulative Pace | I1: Projected Workdays Remaining $E Pace | J1: Projected Date for Proccessing Call if You Applied on Call Date | K1: Projected Calendar Days Remaining | L1: Backlog Amount (Days) | M1: Projected Date using Average of Cumulative Pace
A2: 45889 | B2: 45676 | J2: =IFERROR(WORKDAY($A2, ROUNDUP(MAX(0, _xlfn.DAYS($A2, $B2)) / $H2, 0),Sheet2!$A$2:$A$21),"") | K2: =IFERROR(WORKDAY($A2, ROUNDUP(MAX(0, _xlfn.DAYS($A2, $B2)) / $H2, 0),Sheet2!$A$2:$A$21)-A2,"") | L2: =_xlfn.DAYS(A2,B2) -> 213 | M2: =IFERROR(WORKDAY($A2, ROUNDUP(MAX(0, _xlfn.DAYS($A2, $B2)) / $H$28, 0),Sheet2!$A$2:$A$21),"") -> 46120
A3: 45908 | B3: 45690 | C3: =IF(B3="","",B3-B2) -> 14 | D3: =IF(A3="","",NETWORKDAYS(A2,A3,Sheet2!$A$2:$A$21)-1) -> 12 | E3: =C3/D3 -> 1.1666667 | F3: =SUM($C$3:C3) -> 14 | G3: =SUM($D$3:D3) -> 12 | H3: =F3/G3 -> 1.1666667 | I3: =(A3-B3)/E3 -> 186.85714 | J3: =IFERROR(WORKDAY($A3, ROUNDUP(MAX(0, _xlfn.DAYS($A3, $B3)) / $H3, 0),Sheet2!$A$2:$A$21),"") -> 46181 | K3: =IFERROR(WORKDAY($A3, ROUNDUP(MAX(0, _xlfn.DAYS($A3, $B3)) / $H3, 0),Sheet2!$A$2:$A$21)-A3,"") -> 273 | L3: =_xlfn.DAYS(A3,B3) -> 218 | M3: =IFERROR(WORKDAY($A3, ROUNDUP(MAX(0, _xlfn.DAYS($A3, $B3)) / $H$28, 0),Sheet2!$A$2:$A$21),"") -> 46142
A4: 45915 | B4: 45698 | C4: =IF(B4="","",B4-B3) -> 8 | D4: =IF(A4="","",NETWORKDAYS(A3,A4,Sheet2!$A$2:$A$21)-1) -> 5 | E4: =C4/D4 -> 1.6 | F4: =SUM($C$3:C4) -> 22 | G4: =SUM($D$3:D4) -> 17 | H4: =F4/G4 -> 1.2941176 | I4: =(A4-B4)/E4 -> 135.625 | J4: =IFERROR(WORKDAY($A4, ROUNDUP(MAX(0, _xlfn.DAYS($A4, $B4)) / $H4, 0),Sheet2!$A$2:$A$21),"") -> 46160 | K4: =IFERROR(WORKDAY($A4, ROUNDUP(MAX(0, _xlfn.DAYS($A4, $B4)) / $H4, 0),Sheet2!$A$2:$A$21)-A4,"") -> 245 | L4: =_xlfn.DAYS(A4,B4) -> 217 | M4: =IFERROR(WORKDAY($A4, ROUNDUP(MAX(0, _xlfn.DAYS($A4, $B4)) / $H$28, 0),Sheet2!$A$2:$A$21),"") -> 46148
A5: 45919 | B5: 45707 | C5: =IF(B5="","",B5-B4) -> 9 | D5: =IF(A5="","",NETWORKDAYS(A4,A5,Sheet2!$A$2:$A$21)-1) -> 4 | E5: =C5/D5 -> 2.25 | F5: =SUM($C$3:C5) -> 31 | G5: =SUM($D$3:D5) -> 21 | H5: =F5/G5 -> 1.4761905 | I5: =(A5-B5)/E5 -> 94.222222 | J5: =IFERROR(WORKDAY($A5, ROUNDUP(MAX(0, _xlfn.DAYS($A5, $B5)) / $H5, 0),Sheet2!$A$2:$A$21),"") -> 46132 | K5: =IFERROR(WORKDAY($A5, ROUNDUP(MAX(0, _xlfn.DAYS($A5, $B5)) / $H5, 0),Sheet2!$A$2:$A$21)-A5,"") -> 213 | L5: =_xlfn.DAYS(A5,B5) -> 212 | M5: =IFERROR(WORKDAY($A5, ROUNDUP(MAX(0, _xlfn.DAYS($A5, $B5)) / $H$28, 0),Sheet2!$A$2:$A$21),"") -> 46148
A6: 45923 | B6: 45709 | C6: =IF(B6="","",B6-B5) -> 2 | D6: =IF(A6="","",NETWORKDAYS(A5,A6,Sheet2!$A$2:$A$21)-1) -> 2 | E6: =C6/D6 -> 1 | F6: =SUM($C$3:C6) -> 33 | G6: =SUM($D$3:D6) -> 23 | H6: =F6/G6 -> 1.4347826 | I6: =(A6-B6)/E6 -> 214 | J6: =IFERROR(WORKDAY($A6, ROUNDUP(MAX(0, _xlfn.DAYS($A6, $B6)) / $H6, 0),Sheet2!$A$2:$A$21),"") -> 46142 | K6: =IFERROR(WORKDAY($A6, ROUNDUP(MAX(0, _xlfn.DAYS($A6, $B6)) / $H6, 0),Sheet2!$A$2:$A$21)-A6,"") -> 219 | L6: =_xlfn.DAYS(A6,B6) -> 214 | M6: =IFERROR(WORKDAY($A6, ROUNDUP(MAX(0, _xlfn.DAYS($A6, $B6)) / $H$28, 0),Sheet2!$A$2:$A$21),"") -> 46154
A7: 45924 | B7: 45712 | C7: =IF(B7="","",B7-B6) -> 3 | D7: =IF(A7="","",NETWORKDAYS(A6,A7,Sheet2!$A$2:$A$21)-1) -> 1 | E7: =C7/D7 -> 3 | F7: =SUM($C$3:C7) -> 36 | G7: =SUM($D$3:D7) -> 24 | H7: =F7/G7 -> 1.5 | I7: =(A7-B7)/E7 -> 70.666667 | J7: =IFERROR(WORKDAY($A7, ROUNDUP(MAX(0, _xlfn.DAYS($A7, $B7)) / $H7, 0),Sheet2!$A$2:$A$21),"") -> 46133 | K7: =IFERROR(WORKDAY($A7, ROUNDUP(MAX(0, _xlfn.DAYS($A7, $B7)) / $H7, 0),Sheet2!$A$2:$A$21)-A7,"") -> 209 | L7: =_xlfn.DAYS(A7,B7) -> 212 | M7: =IFERROR(WORKDAY($A7, ROUNDUP(MAX(0, _xlfn.DAYS($A7, $B7)) / $H$28, 0),Sheet2!$A$2:$A$21),"") -> 46153
A8: 45926 | B8: 45712 | C8: 0.5 | D8: =IF(A8="","",NETWORKDAYS(A7,A8,Sheet2!$A$2:$A$21)-1) -> 2 | E8: =C8/D8 -> 0.25 | F8: =SUM($C$3:C8) -> 36.5 | G8: =SUM($D$3:D8) -> 26 | H8: =F8/G8 -> 1.4038462 | I8: =(A8-B8)/E8 -> 856 | J8: =IFERROR(WORKDAY($A8, ROUNDUP(MAX(0, _xlfn.DAYS($A8, $B8)) / $H8, 0),Sheet2!$A$2:$A$21),"") -> 46150 | K8: =IFERROR(WORKDAY($A8, ROUNDUP(MAX(0, _xlfn.DAYS($A8, $B8)) / $H8, 0),Sheet2!$A$2:$A$21)-A8,"") -> 224 | L8: =_xlfn.DAYS(A8,B8) -> 214 | M8: =IFERROR(WORKDAY($A8, ROUNDUP(MAX(0, _xlfn.DAYS($A8, $B8)) / $H$28, 0),Sheet2!$A$2:$A$21),"") -> 46157
A9: 45929 | B9: 45712 | C9: 0.25 | D9: =IF(A9="","",NETWORKDAYS(A8,A9,Sheet2!$A$2:$A$21)-1) -> 1 | E9: =C9/D9 -> 0.25 | F9: =SUM($C$3:C9) -> 36.75 | G9: =SUM($D$3:D9) -> 27 | H9: =F9/G9 -> 1.3611111 | I9: =(A9-B9)/E9 -> 868 | J9: =IFERROR(WORKDAY($A9, ROUNDUP(MAX(0, _xlfn.DAYS($A9, $B9)) / $H9, 0),Sheet2!$A$2:$A$21),"") -> 46162 | K9: =IFERROR(WORKDAY($A9, ROUNDUP(MAX(0, _xlfn.DAYS($A9, $B9)) / $H9, 0),Sheet2!$A$2:$A$21)-A9,"") -> 233 | L9: =_xlfn.DAYS(A9,B9) -> 217 | M9: =IFERROR(WORKDAY($A9, ROUNDUP(MAX(0, _xlfn.DAYS($A9, $B9)) / $H$28, 0),Sheet2!$A$2:$A$21),"") -> 46162
A10: 45930 | B10: 45712 | C10: 0.25 | D10: =IF(A10="","",NETWORKDAYS(A9,A10,Sheet2!$A$2:$A$21)-1) -> 1 | E10: =C10/D10 -> 0.25 | F10: =SUM($C$3:C10) -> 37 | G10: =SUM($D$3:D10) -> 28 | H10: =F10/G10 -> 1.3214286 | I10: =(A10-B10)/E10 -> 872 | J10: =IFERROR(WORKDAY($A10, ROUNDUP(MAX(0, _xlfn.DAYS($A10, $B10)) / $H10, 0),Sheet2!$A$2:$A$21),"") -> 46171 | K10: =IFERROR(WORKDAY($A10, ROUNDUP(MAX(0, _xlfn.DAYS($A10, $B10)) / $H10, 0),Sheet2!$A$2:$A$21)-A10,"") -> 241 | L10: =_xlfn.DAYS(A10,B10) -> 218 | M10: =IFERROR(WORKDAY($A10, ROUNDUP(MAX(0, _xlfn.DAYS($A10, $B10)) / $H$28, 0),Sheet2!$A$2:$A$21),"") -> 46164
A11: 45931 | B11: 45716 | C11: =IF(B11="","",B11-B10) -> 4 | D11: =IF(A11="","",NETWORKDAYS(A10,A11,Sheet2!$A$2:$A$21)-1) -> 1 | E11: =C11/D11 -> 4 | F11: =SUM($C$3:C11) -> 41 | G11: =SUM($D$3:D11) -> 29 | H11: =F11/G11 -> 1.4137931 | I11: =(A11-B11)/E11 -> 53.75 | J11: =IFERROR(WORKDAY($A11, ROUNDUP(MAX(0, _xlfn.DAYS($A11, $B11)) / $H11, 0),Sheet2!$A$2:$A$21),"") -> 46155 | K11: =IFERROR(WORKDAY($A11, ROUNDUP(MAX(0, _xlfn.DAYS($A11, $B11)) / $H11, 0),Sheet2!$A$2:$A$21)-A11,"") -> 224 | L11: =_xlfn.DAYS(A11,B11) -> 215 | M11: =IFERROR(WORKDAY($A11, ROUNDUP(MAX(0, _xlfn.DAYS($A11, $B11)) / $H$28, 0),Sheet2!$A$2:$A$21),"") -> 46163 | R11: Enter Date:
A12: 45937 | B12: 45718 | C12: =IF(B12="","",B12-B11) -> 2 | D12: =IF(A12="","",NETWORKDAYS(A11,A12,Sheet2!$A$2:$A$21)-1) -> 4 | E12: =C12/D12 -> 0.5 | F12: =SUM($C$3:C12) -> 43 | G12: =SUM($D$3:D12) -> 33 | H12: =F12/G12 -> 1.3030303 | I12: =(A12-B12)/E12 -> 438 | J12: =IFERROR(WORKDAY($A12, ROUNDUP(MAX(0, _xlfn.DAYS($A12, $B12)) / $H12, 0),Sheet2!$A$2:$A$21),"") -> 46184 | K12: =IFERROR(WORKDAY($A12, ROUNDUP(MAX(0, _xlfn.DAYS($A12, $B12)) / $H12, 0),Sheet2!$A$2:$A$21)-A12,"") -> 247 | L12: =_xlfn.DAYS(A12,B12) -> 219 | M12: =IFERROR(WORKDAY($A12, ROUNDUP(MAX(0, _xlfn.DAYS($A12, $B12)) / $H$28, 0),Sheet2!$A$2:$A$21),"") -> 46175 | R12: 45764 | V12: 46002
A13: 45945 | B13: 45725 | C13: =IF(B13="","",B13-B12) -> 7 | D13: =IF(A13="","",NETWORKDAYS(A12,A13,Sheet2!$A$2:$A$21)-1) -> 5 | E13: =C13/D13 -> 1.4 | F13: =SUM($C$3:C13) -> 50 | G13: =SUM($D$3:D13) -> 38 | H13: =F13/G13 -> 1.3157895 | I13: =(A13-B13)/E13 -> 157.14286 | J13: =IFERROR(WORKDAY($A13, ROUNDUP(MAX(0, _xlfn.DAYS($A13, $B13)) / $H13, 0),Sheet2!$A$2:$A$21),"") -> 46190 | K13: =IFERROR(WORKDAY($A13, ROUNDUP(MAX(0, _xlfn.DAYS($A13, $B13)) / $H13, 0),Sheet2!$A$2:$A$21)-A13,"") -> 245 | L13: =_xlfn.DAYS(A13,B13) -> 220 | M13: =IFERROR(WORKDAY($A13, ROUNDUP(MAX(0, _xlfn.DAYS($A13, $B13)) / $H$28, 0),Sheet2!$A$2:$A$21),"") -> 46182
A14: 45958 | B14: 45739 | C14: =IF(B14="","",B14-B13) -> 14 | D14: =IF(A14="","",NETWORKDAYS(A13,A14,Sheet2!$A$2:$A$21)-1) -> 9 | E14: =C14/D14 -> 1.5555556 | F14: =SUM($C$3:C14) -> 64 | G14: =SUM($D$3:D14) -> 47 | H14: =F14/G14 -> 1.3617021 | I14: =(A14-B14)/E14 -> 140.78571 | J14: =IFERROR(WORKDAY($A14, ROUNDUP(MAX(0, _xlfn.DAYS($A14, $B14)) / $H14, 0),Sheet2!$A$2:$A$21),"") -> 46192 | K14: =IFERROR(WORKDAY($A14, ROUNDUP(MAX(0, _xlfn.DAYS($A14, $B14)) / $H14, 0),Sheet2!$A$2:$A$21)-A14,"") -> 234 | L14: =_xlfn.DAYS(A14,B14) -> 219 | M14: =IFERROR(WORKDAY($A14, ROUNDUP(MAX(0, _xlfn.DAYS($A14, $B14)) / $H$28, 0),Sheet2!$A$2:$A$21),"") -> 46195 | R14: Expected Date:
A15: 45968 | B15: 45746 | C15: =IF(B15="","",B15-B14) -> 7 | D15: =IF(A15="","",NETWORKDAYS(A14,A15,Sheet2!$A$2:$A$21)-1) -> 8 | E15: =C15/D15 -> 0.875 | F15: =SUM($C$3:C15) -> 71 | G15: =SUM($D$3:D15) -> 55 | H15: =F15/G15 -> 1.2909091 | I15: =(A15-B15)/E15 -> 253.71429 | J15: =IFERROR(WORKDAY($A15, ROUNDUP(MAX(0, _xlfn.DAYS($A15, $B15)) / $H15, 0),Sheet2!$A$2:$A$21),"") -> 46220 | K15: =IFERROR(WORKDAY($A15, ROUNDUP(MAX(0, _xlfn.DAYS($A15, $B15)) / $H15, 0),Sheet2!$A$2:$A$21)-A15,"") -> 252 | L15: =_xlfn.DAYS(A15,B15) -> 222 | M15: =IFERROR(WORKDAY($A15, ROUNDUP(MAX(0, _xlfn.DAYS($A15, $B15)) / $H$28, 0),Sheet2!$A$2:$A$21),"") -> 46210 | R15: =R12*1.00474635070856 -> 45981.212
A16: 45971 | B16: 45752 | C16: =IF(B16="","",B16-B15) -> 6 | D16: =IF(A16="","",NETWORKDAYS(A15,A16,Sheet2!$A$2:$A$21)-1) -> 1 | E16: =C16/D16 -> 6 | F16: =SUM($C$3:C16) -> 77 | G16: =SUM($D$3:D16) -> 56 | H16: =F16/G16 -> 1.375 | I16: =(A16-B16)/E16 -> 36.5 | J16: =IFERROR(WORKDAY($A16, ROUNDUP(MAX(0, _xlfn.DAYS($A16, $B16)) / $H16, 0),Sheet2!$A$2:$A$21),"") -> 46204 | K16: =IFERROR(WORKDAY($A16, ROUNDUP(MAX(0, _xlfn.DAYS($A16, $B16)) / $H16, 0),Sheet2!$A$2:$A$21)-A16,"") -> 233 | L16: =_xlfn.DAYS(A16,B16) -> 219 | M16: =IFERROR(WORKDAY($A16, ROUNDUP(MAX(0, _xlfn.DAYS($A16, $B16)) / $H$28, 0),Sheet2!$A$2:$A$21),"") -> 46209 | V16: =V12/1.00474635070856 -> 45784.69
A17: 45973 | B17: 45753 | C17: =IF(B17="","",B17-B16) -> 1 | D17: =IF(A17="","",NETWORKDAYS(A16,A17,Sheet2!$A$2:$A$21)-1) -> 1 | E17: =C17/D17 -> 1 | F17: =SUM($C$3:C17) -> 78 | G17: =SUM($D$3:D17) -> 57 | H17: =F17/G17 -> 1.3684211 | I17: =(A17-B17)/E17 -> 220 | J17: =IFERROR(WORKDAY($A17, ROUNDUP(MAX(0, _xlfn.DAYS($A17, $B17)) / $H17, 0),Sheet2!$A$2:$A$21),"") -> 46209 | K17: =IFERROR(WORKDAY($A17, ROUNDUP(MAX(0, _xlfn.DAYS($A17, $B17)) / $H17, 0),Sheet2!$A$2:$A$21)-A17,"") -> 236 | L17: =_xlfn.DAYS(A17,B17) -> 220 | M17: =IFERROR(WORKDAY($A17, ROUNDUP(MAX(0, _xlfn.DAYS($A17, $B17)) / $H$28, 0),Sheet2!$A$2:$A$21),"") -> 46210 | R17: +-5 days
A18: 45975 | B18: 45755 | C18: =IF(B18="","",B18-B17) -> 2 | D18: =IF(A18="","",NETWORKDAYS(A17,A18,Sheet2!$A$2:$A$21)-1) -> 2 | E18: =C18/D18 -> 1 | F18: =SUM($C$3:C18) -> 80 | G18: =SUM($D$3:D18) -> 59 | H18: =F18/G18 -> 1.3559322 | I18: =(A18-B18)/E18 -> 220 | J18: =IFERROR(WORKDAY($A18, ROUNDUP(MAX(0, _xlfn.DAYS($A18, $B18)) / $H18, 0),Sheet2!$A$2:$A$21),"") -> 46213 | K18: =IFERROR(WORKDAY($A18, ROUNDUP(MAX(0, _xlfn.DAYS($A18, $B18)) / $H18, 0),Sheet2!$A$2:$A$21)-A18,"") -> 238 | L18: =_xlfn.DAYS(A18,B18) -> 220 | M18: =IFERROR(WORKDAY($A18, ROUNDUP(MAX(0, _xlfn.DAYS($A18, $B18)) / $H$28, 0),Sheet2!$A$2:$A$21),"") -> 46212
A19: 45985 | B19: 45764 | C19: =IF(B19="","",B19-B18) -> 9 | D19: =IF(A19="","",NETWORKDAYS(A18,A19,Sheet2!$A$2:$A$21)-1) -> 6 | E19: =C19/D19 -> 1.5 | F19: =SUM($C$3:C19) -> 89 | G19: =SUM($D$3:D19) -> 65 | H19: =F19/G19 -> 1.3692308 | I19: =(A19-B19)/E19 -> 147.33333 | J19: =IFERROR(WORKDAY($A19, ROUNDUP(MAX(0, _xlfn.DAYS($A19, $B19)) / $H19, 0),Sheet2!$A$2:$A$21),"") -> 46220 | K19: =IFERROR(WORKDAY($A19, ROUNDUP(MAX(0, _xlfn.DAYS($A19, $B19)) / $H19, 0),Sheet2!$A$2:$A$21)-A19,"") -> 235 | L19: =_xlfn.DAYS(A19,B19) -> 221 | M19: =IFERROR(WORKDAY($A19, ROUNDUP(MAX(0, _xlfn.DAYS($A19, $B19)) / $H$28, 0),Sheet2!$A$2:$A$21),"") -> 46223
C20: =IF(B20="","",B20-B19) | D20: =IF(A20="","",NETWORKDAYS(A19,A20,Sheet2!$A$2:$A$21)-1) | E20: =C20/D20 -> #VALUE! | F20: =SUM($C$3:C20) -> 89 | G20: =SUM($D$3:D20) -> 65 | H20: =F20/G20 -> 1.3692308 | I20: =(A20-B20)/E20 -> #VALUE! | J20: =IFERROR(WORKDAY($A20, ROUNDUP(MAX(0, _xlfn.DAYS($A20, $B20)) / $H20, 0),Sheet2!$A$2:$A$21),"") -> 0 | K20: =IFERROR(WORKDAY($A20, ROUNDUP(MAX(0, _xlfn.DAYS($A20, $B20)) / $H20, 0),Sheet2!$A$2:$A$21)-A20,"") -> 0 | M20: =IFERROR(WORKDAY($A20, ROUNDUP(MAX(0, _xlfn.DAYS($A20, $B20)) / $H$28, 0),Sheet2!$A$2:$A$21),"") -> 0
C21: =IF(B21="","",B21-B20) | D21: =IF(A21="","",NETWORKDAYS(A20,A21,Sheet2!$A$2:$A$21)-1) | E21: =C21/D21 -> #VALUE! | F21: =SUM($C$3:C21) -> 89 | G21: =SUM($D$3:D21) -> 65 | H21: =F21/G21 -> 1.3692308 | I21: =(A21-B21)/E21 -> #VALUE! | J21: =IFERROR(WORKDAY($A21, ROUNDUP(MAX(0, _xlfn.DAYS($A21, $B21)) / $H21, 0),Sheet2!$A$2:$A$21),"") -> 0 | K21: =IFERROR(WORKDAY($A21, ROUNDUP(MAX(0, _xlfn.DAYS($A21, $B21)) / $H21, 0),Sheet2!$A$2:$A$21)-A21,"") -> 0 | M21: =IFERROR(WORKDAY($A21, ROUNDUP(MAX(0, _xlfn.DAYS($A21, $B21)) / $H$28, 0),Sheet2!$A$2:$A$21),"") -> 0
C22: =IF(B22="","",B22-B21) | D22: =IF(A22="","",NETWORKDAYS(A21,A22,Sheet2!$A$2:$A$21)-1) | E22: =C22/D22 -> #VALUE! | F22: =SUM($C$3:C22) -> 89 | G22: =SUM($D$3:D22) -> 65 | H22: =F22/G22 -> 1.3692308 | I22: =(A22-B22)/E22 -> #VALUE! | J22: =IFERROR(WORKDAY($A22, ROUNDUP(MAX(0, _xlfn.DAYS($A22, $B22)) / $H22, 0),Sheet2!$A$2:$A$21),"") -> 0 | K22: =IFERROR(WORKDAY($A22, ROUNDUP(MAX(0, _xlfn.DAYS($A22, $B22)) / $H22, 0),Sheet2!$A$2:$A$21)-A22,"") -> 0 | M22: =IFERROR(WORKDAY($A22, ROUNDUP(MAX(0, _xlfn.DAYS($A22, $B22)) / $H$28, 0),Sheet2!$A$2:$A$21),"") -> 0
C23: =IF(B23="","",B23-B22) | D23: =IF(A23="","",NETWORKDAYS(A22,A23,Sheet2!$A$2:$A$21)-1) | E23: =C23/D23 -> #VALUE! | F23: =SUM($C$3:C23) -> 89 | G23: =SUM($D$3:D23) -> 65 | H23: =F23/G23 -> 1.3692308 | I23: =(A23-B23)/E23 -> #VALUE! | J23: =IFERROR(WORKDAY($A23, ROUNDUP(MAX(0, _xlfn.DAYS($A23, $B23)) / $H23, 0),Sheet2!$A$2:$A$21),"") -> 0 | K23: =IFERROR(WORKDAY($A23, ROUNDUP(MAX(0, _xlfn.DAYS($A23, $B23)) / $H23, 0),Sheet2!$A$2:$A$21)-A23,"") -> 0 | M23: =IFERROR(WORKDAY($A23, ROUNDUP(MAX(0, _xlfn.DAYS($A23, $B23)) / $H$28, 0),Sheet2!$A$2:$A$21),"") -> 0
C24: =IF(B24="","",B24-B23) | D24: =IF(A24="","",NETWORKDAYS(A23,A24,Sheet2!$A$2:$A$21)-1) | E24: =C24/D24 -> #VALUE! | F24: =SUM($C$3:C24) -> 89 | G24: =SUM($D$3:D24) -> 65 | H24: =F24/G24 -> 1.3692308 | I24: =(A24-B24)/E24 -> #VALUE! | J24: =IFERROR(WORKDAY($A24, ROUNDUP(MAX(0, _xlfn.DAYS($A24, $B24)) / $H24, 0),Sheet2!$A$2:$A$21),"") -> 0 | K24: =IFERROR(WORKDAY($A24, ROUNDUP(MAX(0, _xlfn.DAYS($A24, $B24)) / $H24, 0),Sheet2!$A$2:$A$21)-A24,"") -> 0 | M24: =IFERROR(WORKDAY($A24, ROUNDUP(MAX(0, _xlfn.DAYS($A24, $B24)) / $H$28, 0),Sheet2!$A$2:$A$21),"") -> 0
C25: =IF(B25="","",B25-B24) | D25: =IF(A25="","",NETWORKDAYS(A24,A25,Sheet2!$A$2:$A$21)-1) | E25: =C25/D25 -> #VALUE! | F25: =SUM($C$3:C25) -> 89 | G25: =SUM($D$3:D25) -> 65 | H25: =F25/G25 -> 1.3692308 | I25: =(A25-B25)/E25 -> #VALUE! | J25: =IFERROR(WORKDAY($A25, ROUNDUP(MAX(0, _xlfn.DAYS($A25, $B25)) / $H25, 0),Sheet2!$A$2:$A$21),"") -> 0 | K25: =IFERROR(WORKDAY($A25, ROUNDUP(MAX(0, _xlfn.DAYS($A25, $B25)) / $H25, 0),Sheet2!$A$2:$A$21)-A25,"") -> 0 | M25: =IFERROR(WORKDAY($A25, ROUNDUP(MAX(0, _xlfn.DAYS($A25, $B25)) / $H$28, 0),Sheet2!$A$2:$A$21),"") -> 0
C26: =IF(B26="","",B26-B25) | D26: =IF(A26="","",NETWORKDAYS(A25,A26,Sheet2!$A$2:$A$21)-1) | E26: =C26/D26 -> #VALUE! | F26: =SUM($C$3:C26) -> 89 | G26: =SUM($D$3:D26) -> 65 | H26: =F26/G26 -> 1.3692308 | I26: =(A26-B26)/E26 -> #VALUE! | J26: =IFERROR(WORKDAY($A26, ROUNDUP(MAX(0, _xlfn.DAYS($A26, $B26)) / $H26, 0),Sheet2!$A$2:$A$21),"") -> 0 | K26: =IFERROR(WORKDAY($A26, ROUNDUP(MAX(0, _xlfn.DAYS($A26, $B26)) / $H26, 0),Sheet2!$A$2:$A$21)-A26,"") -> 0 | M26: =IFERROR(WORKDAY($A26, ROUNDUP(MAX(0, _xlfn.DAYS($A26, $B26)) / $H$28, 0),Sheet2!$A$2:$A$21),"") -> 0
A28: Averages: | C28: =AVERAGE(C3:C19) -> 5.2352941 | D28: =AVERAGE(D3:D19) -> 3.8235294 | E28: =AVERAGE(E3:E19) -> 1.623366 | F28: =AVERAGE(F3:F19) -> 49.367647 | G28: =AVERAGE(G3:G19) -> 36.294118 | H28: =AVERAGE(H3:H19) -> 1.3595266 | I28: =AVERAGE(I3:I19) -> 292.03513 | J28: =AVERAGE(J3:J19) -> 46177.529 | ... L28: =AVERAGE(L3:L19) -> 217.47059
H29: =F28/G28 -> 1.3602107
J37: =IFERROR(WORKDAY($A15, ROUNDUP(MAX(0, _xlfn.DAYS($A15, $B15)) / $H31, 0),Sheet2!$A$2:$A$21),"")
J38: =IFERROR(WORKDAY($A16, ROUNDUP(MAX(0, _xlfn.DAYS($A16, $B16)) / $H32, 0),Sheet2!$A$2:$A$21),"")
J39: =IFERROR(WORKDAY($A17, ROUNDUP(MAX(0, _xlfn.DAYS($A17, $B17)) / $H33, 0),Sheet2!$A$2:$A$21),"")
J40: =IFERROR(WORKDAY($A18, ROUNDUP(MAX(0, _xlfn.DAYS($A18, $B18)) / $H34, 0),Sheet2!$A$2:$A$21),"")
J41: =IFERROR(WORKDAY($A19, ROUNDUP(MAX(0, _xlfn.DAYS($A19, $B19)) / $H35, 0),Sheet2!$A$2:$A$21),"")
J42: =IFERROR(WORKDAY($A20, ROUNDUP(MAX(0, _xlfn.DAYS($A20, $B20)) / $H36, 0),Sheet2!$A$2:$A$21),"")

Sheet Sheet2
A1: Holidays:
A2: 45658 | B2: New Years Day
A3: 45677
A4: 45705
A5: 45803
A6: 45842
A7: 45901
A8: 45943
A9: 45972
A10: 45988
A11: 46016
A12: 46023
A13: 46041
A14: 46069
... A21: 46381

Sheet Sheet3
A1: Call Date | B1: Queue Date | C1: projected processing | H1: {=LINEST(B2:B6, A2:A6, TRUE, TRUE)} -> 0.96010045 | I1: 1617.2204 | M1: {=LINEST(F2:F6, A2:A6, TRUE, TRUE)} -> 0.039899554 | N1: -1617.2204
A2: 45889 | B2: 45677 | F2: =_xlfn.DAYS(A2,B2) -> 212 | H2: 0.11822974 | I2: 5428.0219 | M2: 0.11822974 | N2: 5428.0219
A3: 45908 | B3: 45690 | C3: 46202 | D3: 294 | F3: =_xlfn.DAYS(A3,B3) -> 218 | H3: 0.95648687 | I3: 3.165379 | M3: 0.036574591 | N3: 3.165379
A4: 45915 | B4: 45698 | C4: 46171 | D4: 256 | F4: =_xlfn.DAYS(A4,B4) -> 217 | H4: 65.944701 | I4: 3 | M4: 0.11388922 | N4: 3
A5: 45919 | B5: 45707 | C5: 46139 | D5: 220 | F5: =_xlfn.DAYS(A5,B5) -> 212 | H5: 660.74113 | I5: 30.058873 | M5: 1.1411272 | N5: 30.058873 | R5: =A4-217 -> 45698
A6: 45923 | B6: 45709 | C6: 46148 | D6: 225 | F6: =_xlfn.DAYS(A6,B6) -> 214
E9: Que Month | F9: Predicted Processing | L9: Que Date | M9: Proccessing Date | N9: Type
E10: 45658 | L10: 45677 | M10: 45889 | N10: Actual
E11: 45659 | L11: 45690 | M11: 45908 | N11: Actual
E12: 45660 | L12: 45698 | M12: 45915 | N12: Actual
E13: 45661 | L13: 45707 | M13: 45919 | N13: Actual
E14: 45662 | L14: 45709 | M14: 45923 | N14: Actual
E15: 45663 | N15: Projected
E16: 45664 | N16: Projected
E17: 45665 | N17: Projected
E18: 45666 | N18: Projected
E19: 45667 | N19: Projected
E20: 45668 | N20: Projected
E21: 45669 | N21: Projected
E22: 45670 | N22: Projected | V22: Date Applied: | W22: Expected date 1 | X22: Expected date 2 | Y22: Average | AC22: open date | AD22: High Price | AE22: Low Price | AF22: Closing Price
E23: 45671 | N23: Projected | V23: 45889 | W23: 46118 | X23: 46118 | Y23: 46118 | Z23: 46118 | AB23: 45889 | AC23: 45889 | AD23: 46118 | AE23: 46118 | AF23: 46118
E24: 45672 | N24: Projected | V24: 45908 | W24: 46140 | X24: 46181 | Y24: =(X24-W24)/2 -> 20.5 | Z24: =X24-Y24 -> 46160.5 | AB24: 45908 | AC24: 45908 | AD24: 46181 | AE24: 46140 | AF24: =X24-Y24 -> 46160.5
E25: 45673 | N25: Projected | V25: 45915 | W25: 46146 | X25: 46160 | Y25: =(X25-W25)/2 -> 7 | Z25: =X25-Y25 -> 46153 | AB25: 45915 | AC25: 45915 | AD25: 46160 | AE25: 46146 | AF25: =X25-Y25 -> 46153
E26: 45674 | N26: Projected | V26: 45919 | W26: 46147 | X26: 46132 | Y26: =(X26-W26)/2 -> -7.5 | Z26: =X26-Y26 -> 46139.5 | AB26: 45919 | AC26: 45919 | AD26: 46147 | AE26: 46132 | AF26: =X26-Y26 -> 46139.5
E27: 45675 | N27: Projected | V27: 45923 | W27: 46150 | X27: 46142 | Y27: =(X27-W27)/2 -> -4 | Z27: =X27-Y27 -> 46146 | AB27: 45923 | AC27: 45923 | AD27: 46150 | AE27: 46142 | AF27: =X27-Y27 -> 46146
E28: 45676 | N28: Projected | V28: 45924 | W28: 46150 | X28: 46133 | Y28: =(X28-W28)/2 -> -8.5 | Z28: =X28-Y28 -> 46141.5 | AB28: 45924 | AC28: 45924 | AD28: 46150 | AE28: 46133 | AF28: =X28-Y28 -> 46141.5
E29: 45677 | F29: 212 | G29: Actual | N29: Projected | V29: 45926 | W29: 46155 | X29: 46150 | Y29: =(X29-W29)/2 -> -2.5 | Z29: =X29-Y29 -> 46152.5 | AB29: 45926 | AC29: 45926 | AD29: 46155 | AE29: 46150 | AF29: =X29-Y29 -> 46152.5
E30: 45678 | N30: Projected | V30: 45929 | W30: 46160 | X30: 46162 | Y30: =(X30-W30)/2 -> 1 | Z30: =X30-Y30 -> 46161 | AB30: 45929 | AC30: 45929 | AD30: 46162 | AE30: 46160 | AF30: =X30-Y30 -> 46161
E31: 45679 | N31: Projected | V31: 45930 | W31: 46162 | X31: 46171 | Y31: =(X31-W31)/2 -> 4.5 | Z31: =X31-Y31 -> 46166.5 | AB31: 45930 | AC31: 45930 | AD31: 46171 | AE31: 46162 | AF31: =X31-Y31 -> 46166.5
E32: 45680 | N32: Projected | V32: 45931 | W32: 46161 | X32: 46155 | Y32: =(X32-W32)/2 -> -3 | Z32: =X32-Y32 -> 46158 | AB32: 45931 | AC32: 45931 | AD32: 46161 | AE32: 46155 | AF32: =X32-Y32 -> 46158
E33: 45681 | N33: Projected | V33: 45937 | W33: 46171 | X33: 46184 | Y33: =(X33-W33)/2 -> 6.5 | Z33: =X33-Y33 -> 46177.5 | AB33: 45937 | AC33: 45937 | AD33: 46184 | AE33: 46171 | AF33: =X33-Y33 -> 46177.5
E34: 45682 | N34: Projected
E35: 45683
E36: 45684
E37: 45685
E38: 45686 | V38: 46023
E39: 45687 | V39: 46054
E40: 45688 | V40: 46082 | AB40: 45889 | AC40: 45908 | AD40: 45915 | AE40: 45919 | AF40: 45923 | AG40: 45924 | AH40: 45926 | AI40: 45929 | AJ40: 45930 | AK40: 45931 | AL40: 45937
E41: 45689 | V41: 46113
E42: 45690 | F42: 218 | G42: Actual | V42: 46143
...
